Workbook
Name Annual_Periods: OFFSET(Financials!$E$6,0,1):OFFSET(Financials!$O$6,0,-1)
Name BS_End: Financials!$B$98
Name BS_Start: Financials!$B$49
Name Comp_Name: Assumptions!$B$2
Name Cost_of_Debt: Assumptions!$B$15
Name Cost_of_Equity: Assumptions!$B$22
Name Country_RP: Assumptions!$B$19
Name Current_Price: Assumptions!$B$4
Name DCF_Enterprise_Value: 'DCF (H-Model for TV)'!$C$55
Name DCF_Enterprise_Value: DCF!$C$52
Name DCF_Enterprise_Value_PerShare: 'DCF (H-Model for TV)'!$D$55
Name DCF_Enterprise_Value_PerShare: DCF!$D$52
Name DCF_Equity_Value: 'DCF (H-Model for TV)'!$C$57
Name DCF_Equity_Value: DCF!$C$54
Name DCF_Equity_Value_PerShare: 'DCF (H-Model for TV)'!$D$57
Name DCF_Equity_Value_PerShare: DCF!$D$54
Name Debt_Adj_Factor: Assumptions!$B$13
Name Debt_MV: Assumptions!$B$28
Name Equity_Beta: Assumptions!$B$21
Name Equity_MV: Assumptions!$B$27
Name Equity_Risk_Premium: Assumptions!$B$18
Name Risk_Free_Rate: Assumptions!$B$12
Name Scale_Symbol: Assumptions!$D$6
Name Scaler: Assumptions!$C$6
Name Shares_Out: Assumptions!$B$25
Name Size_RP: Assumptions!$B$20
Name Tax_Rate: Assumptions!$B$14
Name Terminal_Rate: Assumptions!$B$33
Name Total_Capitalization: Assumptions!$B$29
Name WACC: Assumptions!$C$30
Name WACC_Override: 'DCF (H-Model for TV)'!$L$27
Name WACC_Override: DCF!$L$27

Sheet Valuation-->
A1: General Guidelines
A3: 1) | B3: Use all in-cell notes where possible. They are intended to be helpful.
A4: 2) | B4: Color coding is important Excel modeling practice:
B5: Purple = Historical Data
B6: Blue = Assumptions & Projections
B7: Black = Formulas
B8: Green = Links to Other Sheets
B9: User Input Cells
A18: 360 Huntington Fund Valuation Template
A19: Version: Spring 2024 Update
A20: By: Sumukh

Sheet PB_CACHE
A1: H4sIAAAAAAAEAM2QQUvDMBTHu1Wxoh8id0toa+fcoRerKLjDpMXLGDMNDxuWJjVJhe5j+IU1KZ0ePHj1BfJeAv/f+/P3Jp7nfdpy3dX51F5PK2ZofSPlDpV9CxotWaWI6kP0DEozKbIkShKc4hhHIco7bjoFmYDOKMJDtOoqzugj9KXcgchEx/mx4xff2O2A3Y5YXIBihLM9qTjkhNbw++eilO0S3oEPr1tGjbVhtb7lnoyuglw2LVGgggei64LtwfO94GNS9NpAg3PJOQw6je9B2A300O/eOrvN9AfAS7xej6rCKCZeQ9RoKhVn1U8GKY7c+TuAaj4nMzq7iheXKUTXi80mmI5xn/rjcOSG/2jVmTv7At67jZonAgAA

Sheet Summary
C3: =Comp_Name -> Nu Scale | D3: | Per Share Valuation Summary
B19: Models
B21: Valuation Methodology | E21: Low (-10%) | F21: Median | G21: High (+10%) | H21: Weights | J21: Baseline Metrics ($B): | K21: =DCF!$E$31 -> 46022 | L21: Per Share
B22: Discounted Cash Flow (Exit Multiple) | E22: =IFERROR(F22*0.9,"--") -> 126.62037 | F22: ='DCF (H-Model for TV)'!DCF_Equity_Value_PerShare -> 140.6893 | G22: =IFERROR(F22*1.1,"--") -> 154.75823 | H22: 0.15 | J22: Revenue | K22: =INDEX(Financials!$11:$11,MATCH(K$21,Financials!$6:$6,0))*Scaler/(10^9) -> 0.051863 | L22: =K22/Shares_Out*(10^9)/Scaler -> 0.38735529
B23: Market Multiples: EV to Sales | E23: =IFERROR(F23*0.9,"--") -> 38.951435 | F23: =IFERROR('EV-Sales Multiples'!$D$36,"--") -> 43.279372 | G23: =IFERROR(F23*1.1,"--") -> 47.60731 | H23: 0.45 | J23: Gross Margin | K23: =INDEX(Financials!$17:$17,MATCH(K$21,Financials!$6:$6,0))*Scaler/(10^9) -> 0.0414904 | L23: =K23/Shares_Out*(10^9)/Scaler -> 0.30988423
B24: Market Multiples: Market Cap to Sales | E24: =IFERROR(F24*0.9,"--") -> 35.082823 | F24: =IFERROR('Market Cap-Sales Multiples'!D36,"--") -> 38.980915 | G24: =IFERROR(F24*1.1,"--") -> 42.879006 | H24: 0.4 | J24: Operating Income | K24: =INDEX(Financials!$24:$24,MATCH(K$21,Financials!$6:$6,0))*Scaler/(10^9) -> -0.13743695 | L24: =K24/Shares_Out*(10^9)/Scaler -> -1.0264915
B25: Target Price (12-Month) | E25: =SUMPRODUCT(E22:E24,$H$22:$H$24) -> 50.554331 | F25: =SUMPRODUCT(F22:F24,$H$22:$H$24) -> 56.171479 | G25: =SUMPRODUCT(G22:G24,$H$22:$H$24) -> 61.788627 | H25: =SUM(H22:H24) -> 1 | J25: Net Income | K25: =INDEX(Financials!$40:$40,MATCH(K$21,Financials!$6:$6,0))*Scaler/(10^9) -> -0.13743695 | L25: =K25/Shares_Out*(10^9)/Scaler -> -1.0264915
B27: Current Price | F27: =Current_Price -> 44.25
B28: Upside from Current Price (12 Month) | F28: =F25/F27-1 -> 0.26941195
B29: Expected Alpha (12 Month) | F29: =F28-Cost_of_Equity -> 0.095207954
B31: Graph Options -- Do Not Change!
D32: Low | E32: Median | F32: Extra | G32: High | H32: EV
B33: =B22&" "&TEXT(H22,"(0%)") -> Discounted Cash Flow (Exit Multiple) (15%) | D33: =E22 -> 126.62037 | E33: =IFERROR(F22-D33,"NA") -> 14.06893 | F33: =0.025*$F$25 -> 1.404287 | G33: =IFERROR(G22-D33-E33-F33,"NA") -> 12.664643 | H33: =$F$25 -> 56.171479
B34: =#REF!&" "&TEXT(#REF!,"(0%)") -> #REF! | D34: =#REF! -> #REF! | E34: =IFERROR(#REF!-D34,"NA") -> NA | F34: =F$33 -> 1.404287 | G34: =IFERROR(#REF!-D34-E34-F34,"NA") -> NA | H34: =$F$25 -> 56.171479
B35: =B23&" "&TEXT(H23,"(0%)") -> Market Multiples: EV to Sales (45%) | D35: =E23 -> 38.951435 | E35: =IFERROR(F23-D35,"NA") -> 4.3279372 | F35: =F$33 -> 1.404287 | G35: =IFERROR(G23-D35-E35-F35,"NA") -> 2.9236503 | H35: =$F$25 -> 56.171479
B36: =B24&" "&TEXT(H24,"(0%)") -> Market Multiples: Market Cap to Sales (40%) | D36: =E24 -> 35.082823 | E36: =IFERROR(F24-D36,"NA") -> 3.8980915 | F36: =F$33 -> 1.404287 | G36: =IFERROR(G24-D36-E36-F36,"NA") -> 2.4938045 | H36: =$F$25 -> 56.171479

Sheet Assumptions
A1: General Information:
A2: Entity Name | B2: Nu Scale
A3: Ticker Symbol (for Excel API) | B3: #VALUE!
A4: Current Share Price | B4: {=_FV(B3,"Price")} -> 44.25
A5: Currency | B5: USD
A6: Numeral Scaling | B6: Thousands | C6: =IF(B6="",1,IF(B6="Thousands",(10^3),IF(B6="Millions",(10^6),IF(B6="Billions",(10^9))))) -> 1000 | D6: =IF(B6="","Actual",IF(B6="Thousands","K",IF(B6="Millions","M",IF(B6="Billions","B")))) -> K | E6: For the numeral system to work please divide with "decimal" (cell highlighted in blue) while adding values
A7: Start Period | B7: 44560
A9: Cost of Capital Assumptions
A11: Cost of Debt
A12: Risk-Free Rate (10 Year T-Bill) | B12: 0.0409
A13: Debt Adjustment Factor | B13: 1.38
A14: Assumed Effective Tax Rate | B14: 0.1737
A15: After-Tax Cost of Debt | B15: =(Risk_Free_Rate*Debt_Adj_Factor)*(1-Tax_Rate) -> 0.046638025
A17: Cost of Equity
A18: Equity Risk Premium | B18: 0.07 | D18: Equity Risk Premium (S&P 500 US)
A19: Country Risk Premium | B19: 0.006 | D19: Country Risk Premium
A20: Size Risk Premium | B20: 0 | D20: Size Risk Premium
A21: Company Equity Beta | B21: 1.754 | D21: Industry Betas
A22: CAPM Cost of Equity | B22: =(Equity_Beta*(Equity_Risk_Premium+Country_RP))+Risk_Free_Rate+Size_RP -> 0.174204
A24: Company Capitalization & WACC
A25: ="Equity Shares Outstanding ("&Scale_Symbol&")" -> Equity Shares Outstanding (K) | B25: 133890
A26: ="Company Capitalization ($"&Scale_Symbol&")" -> Company Capitalization ($K)
A27: Market Value of Equity | B27: =Current_Price*Shares_Out -> 5924632.5 | C27: =Equity_MV/Total_Capitalization -> 1
A28: Market Value of Debt | B28: 0 | C28: =Debt_MV/Total_Capitalization -> 0
A29: Total Capitalization | B29: =B27+B28 -> 5924632.5 | C29: =C27+C28 -> 1
A30: WACC | C30: =(C27*Cost_of_Equity)+(C28*Cost_of_Debt) -> 0.174204
A32: Sentivity Matrix | B32: Normal | C32: Lower | D32: Higher
A33: Perpetuity Growth Rate | B33: 0.02 | C33: =$B$33+C34 -> 0.015 | D33: =$B$33+D34 -> 0.025
A34: ∆ (+/-) in Perpetuity Growth Rate | C34: -0.005 | D34: 0.005
A35: WACC Range | B35: =WACC -> 0.174204 | C35: =$B$35+C36 -> 0.164204 | D35: =$B$35+D36 -> 0.184204
A36: ∆ (+/-) WACC | C36: -0.01 | D36: 0.01

Sheet Financials
D3: 360 Huntington Fund Free Cash Flow Model | F3: Historical | J3: Projected | P3: Common Size | Z3: Key Assumptions
D6: TTM based on: | F6: =Assumptions!$B$7 -> 44560 | G6: =EOMONTH(OFFSET(G$6,0,-1),12) -> 44926 | H6: =EOMONTH(OFFSET(H$6,0,-1),12) -> 45291 | I6: =EOMONTH(OFFSET(I$6,0,-1),12) -> 45657 | J6: =EOMONTH(OFFSET(J$6,0,-1),12) -> 46022 | K6: =EOMONTH(OFFSET(K$6,0,-1),12) -> 46387 | L6: =EOMONTH(OFFSET(L$6,0,-1),12) -> 46752 | M6: =EOMONTH(OFFSET(M$6,0,-1),12) -> 47118 | N6: =EOMONTH(OFFSET(N$6,0,-1),12) -> 47483 | P6: {=Annual_Periods} -> 44560 | Q6: 44926 | R6: 45291 | S6: 45657 | T6: 46022 | U6: 46387 | V6: 46752 | W6: 47118 | X6: 47483 | Z6: {=INDEX(Annual_Periods,MATCH("Projected",$F$3:$N$3,))} -> 46022 | AA6: =EOMONTH(OFFSET(AA$6,0,-1),12) -> 46387 | AB6: =EOMONTH(OFFSET(AB$6,0,-1),12) -> 46752 | AC6: =EOMONTH(OFFSET(AC$6,0,-1),12) -> 47118 | AD6: =EOMONTH(OFFSET(AD$6,0,-1),12) -> 47483
A8: X | D8: Consolidated Income Statement
D9: Revenues
D10: Sales & Services Revenue | F10: 2862 | G10: 11804 | H10: 22810 | I10: 37045 | J10: =I10*(1+Z10) -> 51863 | K10: =J10*(1+AA10) -> 82980.8 | L10: =K10*(1+AB10) -> 165961.6 | M10: =L10*(1+AC10) -> 365115.52 | N10: =M10*(1+AD10) -> 657207.94 | Z10: 0.4 | AA10: 0.6 | AB10: 1 | AC10: 1.2 | AD10: 0.8
D11: Total Net Revenue | F11: =SUBTOTAL(9,OFFSET(F9,1,0):OFFSET(F11,-1,0)) -> 2862 | G11: =SUBTOTAL(9,OFFSET(G9,1,0):OFFSET(G11,-1,0)) -> 11804 | H11: =SUBTOTAL(9,OFFSET(H9,1,0):OFFSET(H11,-1,0)) -> 22810 | I11: =SUBTOTAL(9,OFFSET(I9,1,0):OFFSET(I11,-1,0)) -> 37045 | J11: =SUBTOTAL(9,OFFSET(J9,1,0):OFFSET(J11,-1,0)) -> 51863 | K11: =SUBTOTAL(9,OFFSET(K9,1,0):OFFSET(K11,-1,0)) -> 82980.8 | L11: =SUBTOTAL(9,OFFSET(L9,1,0):OFFSET(L11,-1,0)) -> 165961.6 | M11: =SUBTOTAL(9,OFFSET(M9,1,0):OFFSET(M11,-1,0)) -> 365115.52 | N11: =SUBTOTAL(9,OFFSET(N9,1,0):OFFSET(N11,-1,0)) -> 657207.94 | P11: {=IFERROR(ABS(OFFSET($E$6,ROW()-ROW(Annual_Periods),MATCH(P$6,Annual_Periods,0)) / OFFSET($E$11,0,MATCH(P$6,Annual_Periods,0))),"NA")} -> 1 | Q11: {=IFERROR(ABS(OFFSET($E$6,ROW()-ROW(Annual_Periods),MATCH(Q$6,Annual_Periods,0)) / OFFSET($E$11,0,MATCH(Q$6,Annual_Periods,0))),"NA")} -> 1 | R11: {=IFERROR(ABS(OFFSET($E$6,ROW()-ROW(Annual_Periods),MATCH(R$6,Annual_Periods,0)) / OFFSET($E$11,0,MATCH(R$6,Annual_Periods,0))),"NA")} -> 1 | S11: {=IFERROR(ABS(OFFSET($E$6,ROW()-ROW(Annual_Periods),MATCH(S$6,Annual_Periods,0)) / OFFSET($E$11,0,MATCH(S$6,Annual_Periods,0))),"NA")} -> 1 | T11: {=IFERROR(ABS(OFFSET($E$6,ROW()-ROW(Annual_Periods),MATCH(T$6,Annual_Periods,0)) / OFFSET($E$11,0,MATCH(T$6,Annual_Periods,0))),"NA")} -> 1 | U11: {=IFERROR(ABS(OFFSET($E$6,ROW()-ROW(Annual_Periods),MATCH(U$6,Annual_Periods,0)) / OFFSET($E$11,0,MATCH(U$6,Annual_Periods,0))),"NA")} -> 1 | V11: {=IFERROR(ABS(OFFSET($E$6,ROW()-ROW(Annual_Periods),MATCH(V$6,Annual_Periods,0)) / OFFSET($E$11,0,MATCH(V$6,Annual_Periods,0))),"NA")} -> 1 | W11: {=IFERROR(ABS(OFFSET($E$6,ROW()-ROW(Annual_Periods),MATCH(W$6,Annual_Periods,0)) / OFFSET($E$11,0,MATCH(W$6,Annual_Periods,0))),"NA")} -> 1 | X11: {=IFERROR(ABS(OFFSET($E$6,ROW()-ROW(Annual_Periods),MATCH(X$6,Annual_Periods,0)) / OFFSET($E$11,0,MATCH(X$6,Annual_Periods,0))),"NA")} -> 1 | AE11: CAGR | AF11: =(N11/I11)^(1/5) - 1 -> 0.77743873
D12: Net Revenue Growth % | F12: =IFERROR(F11/OFFSET(F11,0,-1)-1,"NA") -> NA | G12: =IFERROR(G11/OFFSET(G11,0,-1)-1,"NA") -> 3.1243885 | H12: =IFERROR(H11/OFFSET(H11,0,-1)-1,"NA") -> 0.9323958 | I12: =IFERROR(I11/OFFSET(I11,0,-1)-1,"NA") -> 0.62406839 | J12: =IFERROR(J11/OFFSET(J11,0,-1)-1,"NA") -> 0.4 | K12: =IFERROR(K11/OFFSET(K11,0,-1)-1,"NA") -> 0.6 | L12: =IFERROR(L11/OFFSET(L11,0,-1)-1,"NA") -> 1 | M12: =IFERROR(M11/OFFSET(M11,0,-1)-1,"NA") -> 1.2 | N12: =IFERROR(N11/OFFSET(N11,0,-1)-1,"NA") -> 0.8
D14: COGS (Enter as Negative)
D15: Cost of Goods & Services | F15: -1770 | G15: -7317 | H15: -18961 | I15: -4937 | J15: =-J$11*(Z15) -> -10372.6 | K15: =-K$11*(AA15) -> -20745.2 | L15: =-L$11*(AB15) -> -41490.4 | M15: =-M$11*(AC15) -> -109534.66 | N15: =-N$11*(AD15) -> -230022.78 | P15: {=IFERROR(ABS(OFFSET($E$6,ROW()-ROW(Annual_Periods),MATCH(P$6,Annual_Periods,0)) / OFFSET($E$11,0,MATCH(P$6,Annual_Periods,0))),"NA")} -> 0.61844864 | Q15: {=IFERROR(ABS(OFFSET($E$6,ROW()-ROW(Annual_Periods),MATCH(Q$6,Annual_Periods,0)) / OFFSET($E$11,0,MATCH(Q$6,Annual_Periods,0))),"NA")} -> 0.61987462 | R15: {=IFERROR(ABS(OFFSET($E$6,ROW()-ROW(Annual_Periods),MATCH(R$6,Annual_Periods,0)) / OFFSET($E$11,0,MATCH(R$6,Annual_Periods,0))),"NA")} -> 0.83125822 | S15: {=IFERROR(ABS(OFFSET($E$6,ROW()-ROW(Annual_Periods),MATCH(S$6,Annual_Periods,0)) / OFFSET($E$11,0,MATCH(S$6,Annual_Periods,0))),"NA")} -> 0.13327035 | T15: {=IFERROR(ABS(OFFSET($E$6,ROW()-ROW(Annual_Periods),MATCH(T$6,Annual_Periods,0)) / OFFSET($E$11,0,MATCH(T$6,Annual_Periods,0))),"NA")} -> 0.2 | U15: {=IFERROR(ABS(OFFSET($E$6,ROW()-ROW(Annual_Periods),MATCH(U$6,Annual_Periods,0)) / OFFSET($E$11,0,MATCH(U$6,Annual_Periods,0))),"NA")} -> 0.25 | V15: {=IFERROR(ABS(OFFSET($E$6,ROW()-ROW(Annual_Periods),MATCH(V$6,Annual_Periods,0)) / OFFSET($E$11,0,MATCH(V$6,Annual_Periods,0))),"NA")} -> 0.25 | W15: {=IFERROR(ABS(OFFSET($E$6,ROW()-ROW(Annual_Periods),MATCH(W$6,Annual_Periods,0)) / OFFSET($E$11,0,MATCH(W$6,Annual_Periods,0))),"NA")} -> 0.3 | X15: {=IFERROR(ABS(OFFSET($E$6,ROW()-ROW(Annual_Periods),MATCH(X$6,Annual_Periods,0)) / OFFSET($E$11,0,MATCH(X$6,Annual_Periods,0))),"NA")} -> 0.35 | Z15: 0.2 | AA15: 0.25 | AB15: 0.25 | AC15: 0.3 | AD15: 0.35
D16: Total COGS | F16: =SUBTOTAL(9,OFFSET(F14,1,0):OFFSET(F16,-1,0)) -> -1770 | G16: =SUBTOTAL(9,OFFSET(G14,1,0):OFFSET(G16,-1,0)) -> -7317 | H16: =SUBTOTAL(9,OFFSET(H14,1,0):OFFSET(H16,-1,0)) -> -18961 | I16: =SUBTOTAL(9,OFFSET(I14,1,0):OFFSET(I16,-1,0)) -> -4937 | J16: =SUBTOTAL(9,OFFSET(J14,1,0):OFFSET(J16,-1,0)) -> -10372.6 | K16: =SUBTOTAL(9,OFFSET(K14,1,0):OFFSET(K16,-1,0)) -> -20745.2 | L16: =SUBTOTAL(9,OFFSET(L14,1,0):OFFSET(L16,-1,0)) -> -41490.4 | M16: =SUBTOTAL(9,OFFSET(M14,1,0):OFFSET(M16,-1,0)) -> -109534.66 | N16: =SUBTOTAL(9,OFFSET(N14,1,0):OFFSET(N16,-1,0)) -> -230022.78 | P16: {=IFERROR(ABS(OFFSET($E$6,ROW()-ROW(Annual_Periods),MATCH(P$6,Annual_Periods,0)) / OFFSET($E$11,0,MATCH(P$6,Annual_Periods,0))),"NA")} -> 0.61844864 | Q16: {=IFERROR(ABS(OFFSET($E$6,ROW()-ROW(Annual_Periods),MATCH(Q$6,Annual_Periods,0)) / OFFSET($E$11,0,MATCH(Q$6,Annual_Periods,0))),"NA")} -> 0.61987462 | R16: {=IFERROR(ABS(OFFSET($E$6,ROW()-ROW(Annual_Periods),MATCH(R$6,Annual_Periods,0)) / OFFSET($E$11,0,MATCH(R$6,Annual_Periods,0))),"NA")} -> 0.83125822 | S16: {=IFERROR(ABS(OFFSET($E$6,ROW()-ROW(Annual_Periods),MATCH(S$6,Annual_Periods,0)) / OFFSET($E$11,0,MATCH(S$6,Annual_Periods,0))),"NA")} -> 0.13327035 | T16: {=IFERROR(ABS(OFFSET($E$6,ROW()-ROW(Annual_Periods),MATCH(T$6,Annual_Periods,0)) / OFFSET($E$11,0,MATCH(T$6,Annual_Periods,0))),"NA")} -> 0.2 | U16: {=IFERROR(ABS(OFFSET($E$6,ROW()-ROW(Annual_Periods),MATCH(U$6,Annual_Periods,0)) / OFFSET($E$11,0,MATCH(U$6,Annual_Periods,0))),"NA")} -> 0.25 | V16: {=IFERROR(ABS(OFFSET($E$6,ROW()-ROW(Annual_Periods),MATCH(V$6,Annual_Periods,0)) / OFFSET($E$11,0,MATCH(V$6,Annual_Periods,0))),"NA")} -> 0.25 | W16: {=IFERROR(ABS(OFFSET($E$6,ROW()-ROW(Annual_Periods),MATCH(W$6,Annual_Periods,0)) / OFFSET($E$11,0,MATCH(W$6,Annual_Periods,0))),"NA")} -> 0.3 | X16: {=IFERROR(ABS(OFFSET($E$6,ROW()-ROW(Annual_Periods),MATCH(X$6,Annual_Periods,0)) / OFFSET($E$11,0,MATCH(X$6,Annual_Periods,0))),"NA")} -> 0.35 | AE16: Avg COGS% of Sales | AF16: =AVERAGE(T16:X16) -> 0.27
D17: Gross Profit | F17: =F11+F16 -> 1092 | G17: =G11+G16 -> 4487 | H17: =H11+H16 -> 3849 | I17: =I11+I16 -> 32108 | J17: =J11+J16 -> 41490.4 | K17: =K11+K16 -> 62235.6 | L17: =L11+L16 -> 124471.2 | M17: =M11+M16 -> 255580.86 | N17: =N11+N16 -> 427185.16 | P17: {=IFERROR(OFFSET($E$6,ROW()-ROW(Annual_Periods),MATCH(P$6,Annual_Periods,0)) / OFFSET($E$11,0,MATCH(P$6,Annual_Periods,0)),"NA")} -> 0.38155136 | Q17: {=IFERROR(OFFSET($E$6,ROW()-ROW(Annual_Periods),MATCH(Q$6,Annual_Periods,0)) / OFFSET($E$11,0,MATCH(Q$6,Annual_Periods,0)),"NA")} -> 0.38012538 | R17: {=IFERROR(OFFSET($E$6,ROW()-ROW(Annual_Periods),MATCH(R$6,Annual_Periods,0)) / OFFSET($E$11,0,MATCH(R$6,Annual_Periods,0)),"NA")} -> 0.16874178 | S17: {=IFERROR(OFFSET($E$6,ROW()-ROW(Annual_Periods),MATCH(S$6,Annual_Periods,0)) / OFFSET($E$11,0,MATCH(S$6,Annual_Periods,0)),"NA")} -> 0.86672965 | T17: {=IFERROR(OFFSET($E$6,ROW()-ROW(Annual_Periods),MATCH(T$6,Annual_Periods,0)) / OFFSET($E$11,0,MATCH(T$6,Annual_Periods,0)),"NA")} -> 0.8 | U17: {=IFERROR(OFFSET($E$6,ROW()-ROW(Annual_Periods),MATCH(U$6,Annual_Periods,0)) / OFFSET($E$11,0,MATCH(U$6,Annual_Periods,0)),"NA")} -> 0.75 | V17: {=IFERROR(OFFSET($E$6,ROW()-ROW(Annual_Periods),MATCH(V$6,Annual_Periods,0)) / OFFSET($E$11,0,MATCH(V$6,Annual_Periods,0)),"NA")} -> 0.75 | W17: {=IFERROR(OFFSET($E$6,ROW()-ROW(Annual_Periods),MATCH(W$6,Annual_Periods,0)) / OFFSET($E$11,0,MATCH(W$6,Annual_Periods,0)),"NA")} -> 0.7 | X17: {=IFERROR(OFFSET($E$6,ROW()-ROW(Annual_Periods),MATCH(X$6,Annual_Periods,0)) / OFFSET($E$11,0,MATCH(X$6,Annual_Periods,0)),"NA")} -> 0.65
D18: Total Gross Margin % | F18: =IFERROR(F17/F$11,"NA") -> 0.38155136 | G18: =IFERROR(G17/G$11,"NA") -> 0.38012538 | H18: =IFERROR(H17/H$11,"NA") -> 0.16874178 | I18: =IFERROR(I17/I$11,"NA") -> 0.86672965 | J18: =IFERROR(J17/J$11,"NA") -> 0.8 | K18: =IFERROR(K17/K$11,"NA") -> 0.75 | L18: =IFERROR(L17/L$11,"NA") -> 0.75 | M18: =IFERROR(M17/M$11,"NA") -> 0.7 | N18: =IFERROR(N17/N$11,"NA") -> 0.65
D20: Operating Expenses (Enter as Positive)
D21: SG&A | F21: 45226 | G21: 55307 | H21: 65404 | I21: 75901 | J21: =J$11*(Z21) -> 88167.1 | K21: =K$11*(AA21) -> 95427.92 | L21: =L$11*(AB21) -> 99576.96 | M21: =M$11*(AC21) -> 109534.66 | N21: =N$11*(AD21) -> 177446.14 | P21: {=IFERROR(ABS(OFFSET($E$6,ROW()-ROW(Annual_Periods),MATCH(P$6,Annual_Periods,0)) / OFFSET($E$11,0,MATCH(P$6,Annual_Periods,0))),"NA")} -> 15.802236 | Q21: {=IFERROR(ABS(OFFSET($E$6,ROW()-ROW(Annual_Periods),MATCH(Q$6,Annual_Periods,0)) / OFFSET($E$11,0,MATCH(Q$6,Annual_Periods,0))),"NA")} -> 4.6854456 | R21: {=IFERROR(ABS(OFFSET($E$6,ROW()-ROW(Annual_Periods),MATCH(R$6,Annual_Periods,0)) / OFFSET($E$11,0,MATCH(R$6,Annual_Periods,0))),"NA")} -> 2.8673389 | S21: {=IFERROR(ABS(OFFSET($E$6,ROW()-ROW(Annual_Periods),MATCH(S$6,Annual_Periods,0)) / OFFSET($E$11,0,MATCH(S$6,Annual_Periods,0))),"NA")} -> 2.0488865 | T21: {=IFERROR(ABS(OFFSET($E$6,ROW()-ROW(Annual_Periods),MATCH(T$6,Annual_Periods,0)) / OFFSET($E$11,0,MATCH(T$6,Annual_Periods,0))),"NA")} -> 1.7 | U21: {=IFERROR(ABS(OFFSET($E$6,ROW()-ROW(Annual_Periods),MATCH(U$6,Annual_Periods,0)) / OFFSET($E$11,0,MATCH(U$6,Annual_Periods,0))),"NA")} -> 1.15 | V21: {=IFERROR(ABS(OFFSET($E$6,ROW()-ROW(Annual_Periods),MATCH(V$6,Annual_Periods,0)) / OFFSET($E$11,0,MATCH(V$6,Annual_Periods,0))),"NA")} -> 0.6 | W21: {=IFERROR(ABS(OFFSET($E$6,ROW()-ROW(Annual_Periods),MATCH(W$6,Annual_Periods,0)) / OFFSET($E$11,0,MATCH(W$6,Annual_Periods,0))),"NA")} -> 0.3 | X21: {=IFERROR(ABS(OFFSET($E$6,ROW()-ROW(Annual_Periods),MATCH(X$6,Annual_Periods,0)) / OFFSET($E$11,0,MATCH(X$6,Annual_Periods,0))),"NA")} -> 0.27 | Z21: 1.7 | AA21: 1.15 | AB21: 0.6 | AC21: 0.3 | AD21: 0.27
D22: R&D | F22: 93136 | G22: 127662 | H22: 156050 | I22: 46817 | J22: =J$11*(Z22) -> 49269.85 | K22: =K$11*(AA22) -> 45639.44 | L22: =L$11*(AB22) -> 41490.4 | M22: =M$11*(AC22) -> 36511.552 | N22: =N$11*(AD22) -> 39432.476 | P22: {=IFERROR(ABS(OFFSET($E$6,ROW()-ROW(Annual_Periods),MATCH(P$6,Annual_Periods,0)) / OFFSET($E$11,0,MATCH(P$6,Annual_Periods,0))),"NA")} -> 32.542278 | Q22: {=IFERROR(ABS(OFFSET($E$6,ROW()-ROW(Annual_Periods),MATCH(Q$6,Annual_Periods,0)) / OFFSET($E$11,0,MATCH(Q$6,Annual_Periods,0))),"NA")} -> 10.815147 | R22: {=IFERROR(ABS(OFFSET($E$6,ROW()-ROW(Annual_Periods),MATCH(R$6,Annual_Periods,0)) / OFFSET($E$11,0,MATCH(R$6,Annual_Periods,0))),"NA")} -> 6.8412977 | S22: {=IFERROR(ABS(OFFSET($E$6,ROW()-ROW(Annual_Periods),MATCH(S$6,Annual_Periods,0)) / OFFSET($E$11,0,MATCH(S$6,Annual_Periods,0))),"NA")} -> 1.2637873 | T22: {=IFERROR(ABS(OFFSET($E$6,ROW()-ROW(Annual_Periods),MATCH(T$6,Annual_Periods,0)) / OFFSET($E$11,0,MATCH(T$6,Annual_Periods,0))),"NA")} -> 0.95 | U22: {=IFERROR(ABS(OFFSET($E$6,ROW()-ROW(Annual_Periods),MATCH(U$6,Annual_Periods,0)) / OFFSET($E$11,0,MATCH(U$6,Annual_Periods,0))),"NA")} -> 0.55 | V22: {=IFERROR(ABS(OFFSET($E$6,ROW()-ROW(Annual_Periods),MATCH(V$6,Annual_Periods,0)) / OFFSET($E$11,0,MATCH(V$6,Annual_Periods,0))),"NA")} -> 0.25 | W22: {=IFERROR(ABS(OFFSET($E$6,ROW()-ROW(Annual_Periods),MATCH(W$6,Annual_Periods,0)) / OFFSET($E$11,0,MATCH(W$6,Annual_Periods,0))),"NA")} -> 0.1 | X22: {=IFERROR(ABS(OFFSET($E$6,ROW()-ROW(Annual_Periods),MATCH(X$6,Annual_Periods,0)) / OFFSET($E$11,0,MATCH(X$6,Annual_Periods,0))),"NA")} -> 0.06 | Z22: 0.95 | AA22: 0.55 | AB22: 0.25 | AC22: 0.1 | AD22: 0.06
D23: Other Operating Expenses | F23: 37030 | G23: 51513 | H23: 57960 | I23: 48115 | J23: =J$11*(Z23) -> 41490.4 | K23: =K$11*(AA23) -> 45639.44 | L23: =L$11*(AB23) -> 49788.48 | M23: =M$11*(AC23) -> 51116.173 | N23: =N$11*(AD23) -> 78864.952 | P23: {=IFERROR(ABS(OFFSET($E$6,ROW()-ROW(Annual_Periods),MATCH(P$6,Annual_Periods,0)) / OFFSET($E$11,0,MATCH(P$6,Annual_Periods,0))),"NA")} -> 12.938505 | Q23: {=IFERROR(ABS(OFFSET($E$6,ROW()-ROW(Annual_Periods),MATCH(Q$6,Annual_Periods,0)) / OFFSET($E$11,0,MATCH(Q$6,Annual_Periods,0))),"NA")} -> 4.3640291 | R23: {=IFERROR(ABS(OFFSET($E$6,ROW()-ROW(Annual_Periods),MATCH(R$6,Annual_Periods,0)) / OFFSET($E$11,0,MATCH(R$6,Annual_Periods,0))),"NA")} -> 2.5409908 | S23: {=IFERROR(ABS(OFFSET($E$6,ROW()-ROW(Annual_Periods),MATCH(S$6,Annual_Periods,0)) / OFFSET($E$11,0,MATCH(S$6,Annual_Periods,0))),"NA")} -> 1.2988258 | T23: {=IFERROR(ABS(OFFSET($E$6,ROW()-ROW(Annual_Periods),MATCH(T$6,Annual_Periods,0)) / OFFSET($E$11,0,MATCH(T$6,Annual_Periods,0))),"NA")} -> 0.8 | U23: {=IFERROR(ABS(OFFSET($E$6,ROW()-ROW(Annual_Periods),MATCH(U$6,Annual_Periods,0)) / OFFSET($E$11,0,MATCH(U$6,Annual_Periods,0))),"NA")} -> 0.55 | V23: {=IFERROR(ABS(OFFSET($E$6,ROW()-ROW(Annual_Periods),MATCH(V$6,Annual_Periods,0)) / OFFSET($E$11,0,MATCH(V$6,Annual_Periods,0))),"NA")} -> 0.3 | W23: {=IFERROR(ABS(OFFSET($E$6,ROW()-ROW(Annual_Periods),MATCH(W$6,Annual_Periods,0)) / OFFSET($E$11,0,MATCH(W$6,Annual_Periods,0))),"NA")} -> 0.14 | X23: {=IFERROR(ABS(OFFSET($E$6,ROW()-ROW(Annual_Periods),MATCH(X$6,Annual_Periods,0)) / OFFSET($E$11,0,MATCH(X$6,Annual_Periods,0))),"NA")} -> 0.12 | Z23: 0.8 | AA23: 0.55 | AB23: 0.3 | AC23: 0.14 | AD23: 0.12
D24: Operating Income (EBIT) | F24: =F17-SUBTOTAL(9,OFFSET(F20,1,0):OFFSET(F24,-1,0)) -> -174300 | G24: =G17-SUBTOTAL(9,OFFSET(G20,1,0):OFFSET(G24,-1,0)) -> -229995 | H24: =H17-SUBTOTAL(9,OFFSET(H20,1,0):OFFSET(H24,-1,0)) -> -275565 | I24: =I17-SUBTOTAL(9,OFFSET(I20,1,0):OFFSET(I24,-1,0)) -> -138725 | J24: =J17-SUBTOTAL(9,OFFSET(J20,1,0):OFFSET(J24,-1,0)) -> -137436.95 | K24: =K17-SUBTOTAL(9,OFFSET(K20,1,0):OFFSET(K24,-1,0)) -> -124471.2 | L24: =L17-SUBTOTAL(9,OFFSET(L20,1,0):OFFSET(L24,-1,0)) -> -66384.64 | M24: =M17-SUBTOTAL(9,OFFSET(M20,1,0):OFFSET(M24,-1,0)) -> 58418.483 | N24: =N17-SUBTOTAL(9,OFFSET(N20,1,0):OFFSET(N24,-1,0)) -> 131441.59 | P24: {=IFERROR(OFFSET($E$6,ROW()-ROW(Annual_Periods),MATCH(P$6,Annual_Periods,0)) / OFFSET($E$11,0,MATCH(P$6,Annual_Periods,0)),"NA")} -> -60.901468 | Q24: {=IFERROR(OFFSET($E$6,ROW()-ROW(Annual_Periods),MATCH(Q$6,Annual_Periods,0)) / OFFSET($E$11,0,MATCH(Q$6,Annual_Periods,0)),"NA")} -> -19.484497 | R24: {=IFERROR(OFFSET($E$6,ROW()-ROW(Annual_Periods),MATCH(R$6,Annual_Periods,0)) / OFFSET($E$11,0,MATCH(R$6,Annual_Periods,0)),"NA")} -> -12.080886 | S24: {=IFERROR(OFFSET($E$6,ROW()-ROW(Annual_Periods),MATCH(S$6,Annual_Periods,0)) / OFFSET($E$11,0,MATCH(S$6,Annual_Periods,0)),"NA")} -> -3.7447699 | T24: {=IFERROR(OFFSET($E$6,ROW()-ROW(Annual_Periods),MATCH(T$6,Annual_Periods,0)) / OFFSET($E$11,0,MATCH(T$6,Annual_Periods,0)),"NA")} -> -2.65 | U24: {=IFERROR(OFFSET($E$6,ROW()-ROW(Annual_Periods),MATCH(U$6,Annual_Periods,0)) / OFFSET($E$11,0,MATCH(U$6,Annual_Periods,0)),"NA")} -> -1.5 | V24: {=IFERROR(OFFSET($E$6,ROW()-ROW(Annual_Periods),MATCH(V$6,Annual_Periods,0)) / OFFSET($E$11,0,MATCH(V$6,Annual_Periods,0)),"NA")} -> -0.4 | W24: {=IFERROR(OFFSET($E$6,ROW()-ROW(Annual_Periods),MATCH(W$6,Annual_Periods,0)) / OFFSET($E$11,0,MATCH(W$6,Annual_Periods,0)),"NA")} -> 0.16 | X24: {=IFERROR(OFFSET($E$6,ROW()-ROW(Annual_Periods),MATCH(X$6,Annual_Periods,0)) / OFFSET($E$11,0,MATCH(X$6,Annual_Periods,0)),"NA")} -> 0.2
D25: Depreciation | F25: 2018 | G25: 2521 | H25: 2380 | I25: 1665 | J25: =-J183 -> 1193.067 | K25: =-K183 -> 1581.9741 | L25: =-L183 -> 2601.0363 | M25: =-M183 -> 5106.7651 | N25: =-N183 -> 9489.607 | P25: {=IFERROR(ABS(OFFSET($E$6,ROW()-ROW(Annual_Periods),MATCH(P$6,Annual_Periods,0)) / OFFSET($E$11,0,MATCH(P$6,Annual_Periods,0))),"NA")} -> 0.70510133 | Q25: {=IFERROR(ABS(OFFSET($E$6,ROW()-ROW(Annual_Periods),MATCH(Q$6,Annual_Periods,0)) / OFFSET($E$11,0,MATCH(Q$6,Annual_Periods,0))),"NA")} -> 0.21357167 | R25: {=IFERROR(ABS(OFFSET($E$6,ROW()-ROW(Annual_Periods),MATCH(R$6,Annual_Periods,0)) / OFFSET($E$11,0,MATCH(R$6,Annual_Periods,0))),"NA")} -> 0.1043402 | S25: {=IFERROR(ABS(OFFSET($E$6,ROW()-ROW(Annual_Periods),MATCH(S$6,Annual_Periods,0)) / OFFSET($E$11,0,MATCH(S$6,Annual_Periods,0))),"NA")} -> 0.044945337 | T25: {=IFERROR(ABS(OFFSET($E$6,ROW()-ROW(Annual_Periods),MATCH(T$6,Annual_Periods,0)) / OFFSET($E$11,0,MATCH(T$6,Annual_Periods,0))),"NA")} -> 0.023004203 | U25: {=IFERROR(ABS(OFFSET($E$6,ROW()-ROW(Annual_Periods),MATCH(U$6,Annual_Periods,0)) / OFFSET($E$11,0,MATCH(U$6,Annual_Periods,0))),"NA")} -> 0.019064339 | V25: {=IFERROR(ABS(OFFSET($E$6,ROW()-ROW(Annual_Periods),MATCH(V$6,Annual_Periods,0)) / OFFSET($E$11,0,MATCH(V$6,Annual_Periods,0))),"NA")} -> 0.015672519 | W25: {=IFERROR(ABS(OFFSET($E$6,ROW()-ROW(Annual_Periods),MATCH(W$6,Annual_Periods,0)) / OFFSET($E$11,0,MATCH(W$6,Annual_Periods,0))),"NA")} -> 0.01398671 | X25: {=IFERROR(ABS(OFFSET($E$6,ROW()-ROW(Annual_Periods),MATCH(X$6,Annual_Periods,0)) / OFFSET($E$11,0,MATCH(X$6,Annual_Periods,0))),"NA")} -> 0.014439276
D26: Amortization | F26: 177 | G26: 177 | H26: 177 | I26: 177 | J26: =-J191 -> 237.98759 | K26: =-K191 -> 419.31895 | L26: =-L191 -> 1273.4235 | M26: =-M191 -> 2540.8552 | N26: =-N191 -> 4386.565 | P26: {=IFERROR(ABS(OFFSET($E$6,ROW()-ROW(Annual_Periods),MATCH(P$6,Annual_Periods,0)) / OFFSET($E$11,0,MATCH(P$6,Annual_Periods,0))),"NA")} -> 0.061844864 | Q26: {=IFERROR(ABS(OFFSET($E$6,ROW()-ROW(Annual_Periods),MATCH(Q$6,Annual_Periods,0)) / OFFSET($E$11,0,MATCH(Q$6,Annual_Periods,0))),"NA")} -> 0.014994917 | R26: {=IFERROR(ABS(OFFSET($E$6,ROW()-ROW(Annual_Periods),MATCH(R$6,Annual_Periods,0)) / OFFSET($E$11,0,MATCH(R$6,Annual_Periods,0))),"NA")} -> 0.0077597545 | S26: {=IFERROR(ABS(OFFSET($E$6,ROW()-ROW(Annual_Periods),MATCH(S$6,Annual_Periods,0)) / OFFSET($E$11,0,MATCH(S$6,Annual_Periods,0))),"NA")} -> 0.0047779727 | T26: {=IFERROR(ABS(OFFSET($E$6,ROW()-ROW(Annual_Periods),MATCH(T$6,Annual_Periods,0)) / OFFSET($E$11,0,MATCH(T$6,Annual_Periods,0))),"NA")} -> 0.004588774 | U26: {=IFERROR(ABS(OFFSET($E$6,ROW()-ROW(Annual_Periods),MATCH(U$6,Annual_Periods,0)) / OFFSET($E$11,0,MATCH(U$6,Annual_Periods,0))),"NA")} -> 0.0050532044 | V26: {=IFERROR(ABS(OFFSET($E$6,ROW()-ROW(Annual_Periods),MATCH(V$6,Annual_Periods,0)) / OFFSET($E$11,0,MATCH(V$6,Annual_Periods,0))),"NA")} -> 0.0076730007 | W26: {=IFERROR(ABS(OFFSET($E$6,ROW()-ROW(Annual_Periods),MATCH(W$6,Annual_Periods,0)) / OFFSET($E$11,0,MATCH(W$6,Annual_Periods,0))),"NA")} -> 0.0069590447 | X26: {=IFERROR(ABS(OFFSET($E$6,ROW()-ROW(Annual_Periods),MATCH(X$6,Annual_Periods,0)) / OFFSET($E$11,0,MATCH(X$6,Annual_Periods,0))),"NA")} -> 0.0066745466
D27: Total Operating Expenses | F27: =SUBTOTAL(9,F21:F23) -> 175392 | G27: =SUBTOTAL(9,G21:G23) -> 234482 | H27: =SUBTOTAL(9,H21:H23) -> 279414 | I27: =SUBTOTAL(9,I21:I23) -> 170833 | J27: =SUBTOTAL(9,J21:J23) -> 178927.35 | K27: =SUBTOTAL(9,K21:K23) -> 186706.8 | L27: =SUBTOTAL(9,L21:L23) -> 190855.84 | M27: =SUBTOTAL(9,M21:M23) -> 197162.38 | N27: =SUBTOTAL(9,N21:N23) -> 295743.57 | P27: {=IFERROR(ABS(OFFSET($E$6,ROW()-ROW(Annual_Periods),MATCH(P$6,Annual_Periods,0)) / OFFSET($E$11,0,MATCH(P$6,Annual_Periods,0))),"NA")} -> 61.283019 | Q27: {=IFERROR(ABS(OFFSET($E$6,ROW()-ROW(Annual_Periods),MATCH(Q$6,Annual_Periods,0)) / OFFSET($E$11,0,MATCH(Q$6,Annual_Periods,0))),"NA")} -> 19.864622 | R27: {=IFERROR(ABS(OFFSET($E$6,ROW()-ROW(Annual_Periods),MATCH(R$6,Annual_Periods,0)) / OFFSET($E$11,0,MATCH(R$6,Annual_Periods,0))),"NA")} -> 12.249627 | S27: {=IFERROR(ABS(OFFSET($E$6,ROW()-ROW(Annual_Periods),MATCH(S$6,Annual_Periods,0)) / OFFSET($E$11,0,MATCH(S$6,Annual_Periods,0))),"NA")} -> 4.6114995 | T27: {=IFERROR(ABS(OFFSET($E$6,ROW()-ROW(Annual_Periods),MATCH(T$6,Annual_Periods,0)) / OFFSET($E$11,0,MATCH(T$6,Annual_Periods,0))),"NA")} -> 3.45 | U27: {=IFERROR(ABS(OFFSET($E$6,ROW()-ROW(Annual_Periods),MATCH(U$6,Annual_Periods,0)) / OFFSET($E$11,0,MATCH(U$6,Annual_Periods,0))),"NA")} -> 2.25 | V27: {=IFERROR(ABS(OFFSET($E$6,ROW()-ROW(Annual_Periods),MATCH(V$6,Annual_Periods,0)) / OFFSET($E$11,0,MATCH(V$6,Annual_Periods,0))),"NA")} -> 1.15 | W27: {=IFERROR(ABS(OFFSET($E$6,ROW()-ROW(Annual_Periods),MATCH(W$6,Annual_Periods,0)) / OFFSET($E$11,0,MATCH(W$6,Annual_Periods,0))),"NA")} -> 0.54 | X27: {=IFERROR(ABS(OFFSET($E$6,ROW()-ROW(Annual_Periods),MATCH(X$6,Annual_Periods,0)) / OFFSET($E$11,0,MATCH(X$6,Annual_Periods,0))),"NA")} -> 0.45 | AE27: Avg Opex% of Sales | AF27: =AVERAGE(T27:X27) -> 1.568
D28: EBITDA | F28: =F24+F25+F26 -> -172105 | G28: =G24+G25+G26 -> -227297 | H28: =H24+H25+H26 -> -273008 | I28: =I24+I25+I26 -> -136883 | J28: =J24+J25+J26 -> -136005.9 | K28: =K24+K25+K26 -> -122469.91 | L28: =L24+L25+L26 -> -62510.18 | M28: =M24+M25+M26 -> 66066.103 | N28: =N24+N25+N26 -> 145317.76 | P28: {=IFERROR(OFFSET($E$6,ROW()-ROW(Annual_Periods),MATCH(P$6,Annual_Periods,0)) / OFFSET($E$11,0,MATCH(P$6,Annual_Periods,0)),"NA")} -> -60.134521 | Q28: {=IFERROR(OFFSET($E$6,ROW()-ROW(Annual_Periods),MATCH(Q$6,Annual_Periods,0)) / OFFSET($E$11,0,MATCH(Q$6,Annual_Periods,0)),"NA")} -> -19.25593 | R28: {=IFERROR(OFFSET($E$6,ROW()-ROW(Annual_Periods),MATCH(R$6,Annual_Periods,0)) / OFFSET($E$11,0,MATCH(R$6,Annual_Periods,0)),"NA")} -> -11.968786 | S28: {=IFERROR(OFFSET($E$6,ROW()-ROW(Annual_Periods),MATCH(S$6,Annual_Periods,0)) / OFFSET($E$11,0,MATCH(S$6,Annual_Periods,0)),"NA")} -> -3.6950466 | T28: {=IFERROR(OFFSET($E$6,ROW()-ROW(Annual_Periods),MATCH(T$6,Annual_Periods,0)) / OFFSET($E$11,0,MATCH(T$6,Annual_Periods,0)),"NA")} -> -2.622407 | U28: {=IFERROR(OFFSET($E$6,ROW()-ROW(Annual_Periods),MATCH(U$6,Annual_Periods,0)) / OFFSET($E$11,0,MATCH(U$6,Annual_Periods,0)),"NA")} -> -1.4758825 | V28: {=IFERROR(OFFSET($E$6,ROW()-ROW(Annual_Periods),MATCH(V$6,Annual_Periods,0)) / OFFSET($E$11,0,MATCH(V$6,Annual_Periods,0)),"NA")} -> -0.37665448 | W28: {=IFERROR(OFFSET($E$6,ROW()-ROW(Annual_Periods),MATCH(W$6,Annual_Periods,0)) / OFFSET($E$11,0,MATCH(W$6,Annual_Periods,0)),"NA")} -> 0.18094576 | X28: {=IFERROR(OFFSET($E$6,ROW()-ROW(Annual_Periods),MATCH(X$6,Annual_Periods,0)) / OFFSET($E$11,0,MATCH(X$6,Annual_Periods,0)),"NA")} -> 0.22111382
D29: EBITDA Margin % | F29: =IFERROR(F28/F$11,"NA") -> -60.134521 | G29: =IFERROR(G28/G$11,"NA") -> -19.25593 | H29: =IFERROR(H28/H$11,"NA") -> -11.968786 | I29: =IFERROR(I28/I$11,"NA") -> -3.6950466 | J29: =IFERROR(J28/J$11,"NA") -> -2.622407 | K29: =IFERROR(K28/K$11,"NA") -> -1.4758825 | L29: =IFERROR(L28/L$11,"NA") -> -0.37665448 | M29: =IFERROR(M28/M$11,"NA") -> 0.18094576 | N29: =IFERROR(N28/N$11,"NA") -> 0.22111382
D30: Total Operating (EBIT) Margin % | F30: =IFERROR(F24/F$11,"NA") -> -60.901468 | G30: =IFERROR(G24/G$11,"NA") -> -19.484497 | H30: =IFERROR(H24/H$11,"NA") -> -12.080886 | I30: =IFERROR(I24/I$11,"NA") -> -3.7447699 | J30: =IFERROR(J24/J$11,"NA") -> -2.65 | K30: =IFERROR(K24/K$11,"NA") -> -1.5 | L30: =IFERROR(L24/L$11,"NA") -> -0.4 | M30: =IFERROR(M24/M$11,"NA") -> 0.16 | N30: =IFERROR(N24/N$11,"NA") -> 0.2
D32: Other Income (Expense)
D33: Interest Income (Positive) | F33: - | G33: 3760 | H33: 10792 | I33: 0 | J33: =J$11*(Z33) -> 0 | K33: =K$11*(AA33) -> 0 | L33: =L$11*(AB33) -> 0 | M33: =M$11*(AC33) -> 0 | N33: =N$11*(AD33) -> 0 | P33: {=IFERROR(ABS(OFFSET($E$6,ROW()-ROW(Annual_Periods),MATCH(P$6,Annual_Periods,0)) / OFFSET($E$11,0,MATCH(P$6,Annual_Periods,0))),"NA")} -> NA | Q33: {=IFERROR(ABS(OFFSET($E$6,ROW()-ROW(Annual_Periods),MATCH(Q$6,Annual_Periods,0)) / OFFSET($E$11,0,MATCH(Q$6,Annual_Periods,0))),"NA")} -> 0.31853609 | R33: {=IFERROR(ABS(OFFSET($E$6,ROW()-ROW(Annual_Periods),MATCH(R$6,Annual_Periods,0)) / OFFSET($E$11,0,MATCH(R$6,Annual_Periods,0))),"NA")} -> 0.47312582 | S33: {=IFERROR(ABS(OFFSET($E$6,ROW()-ROW(Annual_Periods),MATCH(S$6,Annual_Periods,0)) / OFFSET($E$11,0,MATCH(S$6,Annual_Periods,0))),"NA")} -> 0 | T33: {=IFERROR(ABS(OFFSET($E$6,ROW()-ROW(Annual_Periods),MATCH(T$6,Annual_Periods,0)) / OFFSET($E$11,0,MATCH(T$6,Annual_Periods,0))),"NA")} -> 0 | U33: {=IFERROR(ABS(OFFSET($E$6,ROW()-ROW(Annual_Periods),MATCH(U$6,Annual_Periods,0)) / OFFSET($E$11,0,MATCH(U$6,Annual_Periods,0))),"NA")} -> 0 | V33: {=IFERROR(ABS(OFFSET($E$6,ROW()-ROW(Annual_Periods),MATCH(V$6,Annual_Periods,0)) / OFFSET($E$11,0,MATCH(V$6,Annual_Periods,0))),"NA")} -> 0 | W33: {=IFERROR(ABS(OFFSET($E$6,ROW()-ROW(Annual_Periods),MATCH(W$6,Annual_Periods,0)) / OFFSET($E$11,0,MATCH(W$6,Annual_Periods,0))),"NA")} -> 0 | X33: {=IFERROR(ABS(OFFSET($E$6,ROW()-ROW(Annual_Periods),MATCH(X$6,Annual_Periods,0)) / OFFSET($E$11,0,MATCH(X$6,Annual_Periods,0))),"NA")} -> 0
D34: Interest Expense (Negative) | F34: -1715 | G34: - | H34: - | I34: - | J34: =J$11*(Z34) -> 0 | K34: =K$11*(AA34) -> 0 | L34: =L$11*(AB34) -> 0 | M34: =M$11*(AC34) -> 0 | N34: =N$11*(AD34) -> 0 | P34: {=IFERROR(ABS(OFFSET($E$6,ROW()-ROW(Annual_Periods),MATCH(P$6,Annual_Periods,0)) / OFFSET($E$11,0,MATCH(P$6,Annual_Periods,0))),"NA")} -> 0.59923131 | Q34: {=IFERROR(ABS(OFFSET($E$6,ROW()-ROW(Annual_Periods),MATCH(Q$6,Annual_Periods,0)) / OFFSET($E$11,0,MATCH(Q$6,Annual_Periods,0))),"NA")} -> NA | R34: {=IFERROR(ABS(OFFSET($E$6,ROW()-ROW(Annual_Periods),MATCH(R$6,Annual_Periods,0)) / OFFSET($E$11,0,MATCH(R$6,Annual_Periods,0))),"NA")} -> NA | S34: {=IFERROR(ABS(OFFSET($E$6,ROW()-ROW(Annual_Periods),MATCH(S$6,Annual_Periods,0)) / OFFSET($E$11,0,MATCH(S$6,Annual_Periods,0))),"NA")} -> NA | T34: {=IFERROR(ABS(OFFSET($E$6,ROW()-ROW(Annual_Periods),MATCH(T$6,Annual_Periods,0)) / OFFSET($E$11,0,MATCH(T$6,Annual_Periods,0))),"NA")} -> 0 | U34: {=IFERROR(ABS(OFFSET($E$6,ROW()-ROW(Annual_Periods),MATCH(U$6,Annual_Periods,0)) / OFFSET($E$11,0,MATCH(U$6,Annual_Periods,0))),"NA")} -> 0 | V34: {=IFERROR(ABS(OFFSET($E$6,ROW()-ROW(Annual_Periods),MATCH(V$6,Annual_Periods,0)) / OFFSET($E$11,0,MATCH(V$6,Annual_Periods,0))),"NA")} -> 0 | W34: {=IFERROR(ABS(OFFSET($E$6,ROW()-ROW(Annual_Periods),MATCH(W$6,Annual_Periods,0)) / OFFSET($E$11,0,MATCH(W$6,Annual_Periods,0))),"NA")} -> 0 | X34: {=IFERROR(ABS(OFFSET($E$6,ROW()-ROW(Annual_Periods),MATCH(X$6,Annual_Periods,0)) / OFFSET($E$11,0,MATCH(X$6,Annual_Periods,0))),"NA")} -> 0
D35: Total Other Income (Expense) | F35: =SUBTOTAL(9,OFFSET(F32,1,0):OFFSET(F35,-1,0)) -> -1715 | G35: =SUBTOTAL(9,OFFSET(G32,1,0):OFFSET(G35,-1,0)) -> 3760 | H35: =SUBTOTAL(9,OFFSET(H32,1,0):OFFSET(H35,-1,0)) -> 10792 | I35: =SUBTOTAL(9,OFFSET(I32,1,0):OFFSET(I35,-1,0)) -> 0 | J35: =SUBTOTAL(9,OFFSET(J32,1,0):OFFSET(J35,-1,0)) -> 0 | K35: =SUBTOTAL(9,OFFSET(K32,1,0):OFFSET(K35,-1,0)) -> 0 | L35: =SUBTOTAL(9,OFFSET(L32,1,0):OFFSET(L35,-1,0)) -> 0 | M35: =SUBTOTAL(9,OFFSET(M32,1,0):OFFSET(M35,-1,0)) -> 0 | N35: =SUBTOTAL(9,OFFSET(N32,1,0):OFFSET(N35,-1,0)) -> 0 | P35: {=IFERROR(ABS(OFFSET($E$6,ROW()-ROW(Annual_Periods),MATCH(P$6,Annual_Periods,0)) / OFFSET($E$11,0,MATCH(P$6,Annual_Periods,0))),"NA")} -> 0.59923131 | Q35: {=IFERROR(ABS(OFFSET($E$6,ROW()-ROW(Annual_Periods),MATCH(Q$6,Annual_Periods,0)) / OFFSET($E$11,0,MATCH(Q$6,Annual_Periods,0))),"NA")} -> 0.31853609 | R35: {=IFERROR(ABS(OFFSET($E$6,ROW()-ROW(Annual_Periods),MATCH(R$6,Annual_Periods,0)) / OFFSET($E$11,0,MATCH(R$6,Annual_Periods,0))),"NA")} -> 0.47312582 | S35: {=IFERROR(ABS(OFFSET($E$6,ROW()-ROW(Annual_Periods),MATCH(S$6,Annual_Periods,0)) / OFFSET($E$11,0,MATCH(S$6,Annual_Periods,0))),"NA")} -> 0 | T35: {=IFERROR(ABS(OFFSET($E$6,ROW()-ROW(Annual_Periods),MATCH(T$6,Annual_Periods,0)) / OFFSET($E$11,0,MATCH(T$6,Annual_Periods,0))),"NA")} -> 0 | U35: {=IFERROR(ABS(OFFSET($E$6,ROW()-ROW(Annual_Periods),MATCH(U$6,Annual_Periods,0)) / OFFSET($E$11,0,MATCH(U$6,Annual_Periods,0))),"NA")} -> 0 | V35: {=IFERROR(ABS(OFFSET($E$6,ROW()-ROW(Annual_Periods),MATCH(V$6,Annual_Periods,0)) / OFFSET($E$11,0,MATCH(V$6,Annual_Periods,0))),"NA")} -> 0 | W35: {=IFERROR(ABS(OFFSET($E$6,ROW()-ROW(Annual_Periods),MATCH(W$6,Annual_Periods,0)) / OFFSET($E$11,0,MATCH(W$6,Annual_Periods,0))),"NA")} -> 0 | X35: {=IFERROR(ABS(OFFSET($E$6,ROW()-ROW(Annual_Periods),MATCH(X$6,Annual_Periods,0)) / OFFSET($E$11,0,MATCH(X$6,Annual_Periods,0))),"NA")} -> 0
D36: EBT | F36: =F24+F35 -> -176015 | G36: =G24+G35 -> -226235 | H36: =H24+H35 -> -264773 | I36: =I24+I35 -> -138725 | J36: =J24+J35 -> -137436.95 | K36: =K24+K35 -> -124471.2 | L36: =L24+L35 -> -66384.64 | M36: =M24+M35 -> 58418.483 | N36: =N24+N35 -> 131441.59 | P36: {=IFERROR(OFFSET($E$6,ROW()-ROW(Annual_Periods),MATCH(P$6,Annual_Periods,0)) / OFFSET($E$11,0,MATCH(P$6,Annual_Periods,0)),"NA")} -> -61.500699 | Q36: {=IFERROR(OFFSET($E$6,ROW()-ROW(Annual_Periods),MATCH(Q$6,Annual_Periods,0)) / OFFSET($E$11,0,MATCH(Q$6,Annual_Periods,0)),"NA")} -> -19.165961 | R36: {=IFERROR(OFFSET($E$6,ROW()-ROW(Annual_Periods),MATCH(R$6,Annual_Periods,0)) / OFFSET($E$11,0,MATCH(R$6,Annual_Periods,0)),"NA")} -> -11.60776 | S36: {=IFERROR(OFFSET($E$6,ROW()-ROW(Annual_Periods),MATCH(S$6,Annual_Periods,0)) / OFFSET($E$11,0,MATCH(S$6,Annual_Periods,0)),"NA")} -> -3.7447699 | T36: {=IFERROR(OFFSET($E$6,ROW()-ROW(Annual_Periods),MATCH(T$6,Annual_Periods,0)) / OFFSET($E$11,0,MATCH(T$6,Annual_Periods,0)),"NA")} -> -2.65 | U36: {=IFERROR(OFFSET($E$6,ROW()-ROW(Annual_Periods),MATCH(U$6,Annual_Periods,0)) / OFFSET($E$11,0,MATCH(U$6,Annual_Periods,0)),"NA")} -> -1.5 | V36: {=IFERROR(OFFSET($E$6,ROW()-ROW(Annual_Periods),MATCH(V$6,Annual_Periods,0)) / OFFSET($E$11,0,MATCH(V$6,Annual_Periods,0)),"NA")} -> -0.4 | W36: {=IFERROR(OFFSET($E$6,ROW()-ROW(Annual_Periods),MATCH(W$6,Annual_Periods,0)) / OFFSET($E$11,0,MATCH(W$6,Annual_Periods,0)),"NA")} -> 0.16 | X36: {=IFERROR(OFFSET($E$6,ROW()-ROW(Annual_Periods),MATCH(X$6,Annual_Periods,0)) / OFFSET($E$11,0,MATCH(X$6,Annual_Periods,0)),"NA")} -> 0.2
D38: Taxation
D39: Taxes (Enter as Negative for Taxes Paid) | J39: =-J$36*(Z39) -> 0 | K39: =-K$36*(AA39) -> 0 | L39: =-L$36*(AB39) -> 0 | M39: =-M$36*(AC39) -> 0 | N39: =-N$36*(AD39) -> 0 | P39: =-F39/F36 -> 0 | Q39: =-G39/G36 -> 0 | R39: =-H39/H36 -> 0 | S39: =-I39/I36 -> 0 | T39: =-J39/J36 -> 0 | U39: =-K39/K36 -> 0 | V39: =-L39/L36 -> 0 | W39: =-M39/M36 -> 0 | X39: =-N39/N36 -> 0
D40: Net Income from Continuing Operations | F40: =F36+F39 -> -176015 | G40: =G36+G39 -> -226235 | H40: =H36+H39 -> -264773 | I40: =I36+I39 -> -138725 | J40: =J36+J39 -> -137436.95 | K40: =K36+K39 -> -124471.2 | L40: =L36+L39 -> -66384.64 | M40: =M36+M39 -> 58418.483 | N40: =N36+N39 -> 131441.59 | P40: {=IFERROR(OFFSET($E$6,ROW()-ROW(Annual_Periods),MATCH(P$6,Annual_Periods,0)) / OFFSET($E$11,0,MATCH(P$6,Annual_Periods,0)),"NA")} -> -61.500699 | Q40: {=IFERROR(OFFSET($E$6,ROW()-ROW(Annual_Periods),MATCH(Q$6,Annual_Periods,0)) / OFFSET($E$11,0,MATCH(Q$6,Annual_Periods,0)),"NA")} -> -19.165961 | R40: {=IFERROR(OFFSET($E$6,ROW()-ROW(Annual_Periods),MATCH(R$6,Annual_Periods,0)) / OFFSET($E$11,0,MATCH(R$6,Annual_Periods,0)),"NA")} -> -11.60776 | S40: {=IFERROR(OFFSET($E$6,ROW()-ROW(Annual_Periods),MATCH(S$6,Annual_Periods,0)) / OFFSET($E$11,0,MATCH(S$6,Annual_Periods,0)),"NA")} -> -3.7447699 | T40: {=IFERROR(OFFSET($E$6,ROW()-ROW(Annual_Periods),MATCH(T$6,Annual_Periods,0)) / OFFSET($E$11,0,MATCH(T$6,Annual_Periods,0)),"NA")} -> -2.65 | U40: {=IFERROR(OFFSET($E$6,ROW()-ROW(Annual_Periods),MATCH(U$6,Annual_Periods,0)) / OFFSET($E$11,0,MATCH(U$6,Annual_Periods,0)),"NA")} -> -1.5 | V40: {=IFERROR(OFFSET($E$6,ROW()-ROW(Annual_Periods),MATCH(V$6,Annual_Periods,0)) / OFFSET($E$11,0,MATCH(V$6,Annual_Periods,0)),"NA")} -> -0.4 | W40: {=IFERROR(OFFSET($E$6,ROW()-ROW(Annual_Periods),MATCH(W$6,Annual_Periods,0)) / OFFSET($E$11,0,MATCH(W$6,Annual_Periods,0)),"NA")} -> 0.16 | X40: {=IFERROR(OFFSET($E$6,ROW()-ROW(Annual_Periods),MATCH(X$6,Annual_Periods,0)) / OFFSET($E$11,0,MATCH(X$6,Annual_Periods,0)),"NA")} -> 0.2
D41: Profit Margin % | F41: =IFERROR(F40/F$11,"NA") -> -61.500699 | G41: =IFERROR(G40/G$11,"NA") -> -19.165961 | H41: =IFERROR(H40/H$11,"NA") -> -11.60776 | I41: =IFERROR(I40/I$11,"NA") -> -3.7447699 | J41: =IFERROR(J40/J$11,"NA") -> -2.65 | K41: =IFERROR(K40/K$11,"NA") -> -1.5 | L41: =IFERROR(L40/L$11,"NA") -> -0.4 | M41: =IFERROR(M40/M$11,"NA") -> 0.16 | N41: =IFERROR(N40/N$11,"NA") -> 0.2
D43: Retained Earnings
D44: Beginning of Period | G44: =OFFSET(G47,0,-1) -> - | H44: =OFFSET(H47,0,-1) -> 296748 | I44: =OFFSET(I47,0,-1) -> 333888 | J44: =OFFSET(J47,0,-1) -> 995745 | K44: =OFFSET(K47,0,-1) -> 858308.05 | L44: =OFFSET(L47,0,-1) -> 733836.85 | M44: =OFFSET(M47,0,-1) -> 667452.21 | N44: =OFFSET(N47,0,-1) -> 725870.69
D45: Net Income | F45: =F$40 -> -176015 | G45: =G$40 -> -226235 | H45: =H$40 -> -264773 | I45: =I$40 -> -138725 | J45: =J$40 -> -137436.95 | K45: =K$40 -> -124471.2 | L45: =L$40 -> -66384.64 | M45: =M$40 -> 58418.483 | N45: =N$40 -> 131441.59
D46: PLUG (Dividends, Other Adj, Etc.) | F46: =F47-F45-F44 -> #VALUE! | G46: =G47-G45-G44 -> #VALUE! | H46: =H47-H45-H44 -> 301913 | I46: =I47-I45-I44 -> 800582 | J46: 0 | K46: 0 | L46: 0 | M46: 0 | N46: 0
D47: End of Period | F47: =F$94 -> - | G47: =G$94 -> 296748 | H47: =H$94 -> 333888 | I47: =I$94 -> 995745 | J47: =SUBTOTAL(9,OFFSET(J43,1,0):OFFSET(J47,-1,0)) -> 858308.05 | K47: =SUBTOTAL(9,OFFSET(K43,1,0):OFFSET(K47,-1,0)) -> 733836.85 | L47: =SUBTOTAL(9,OFFSET(L43,1,0):OFFSET(L47,-1,0)) -> 667452.21 | M47: =SUBTOTAL(9,OFFSET(M43,1,0):OFFSET(M47,-1,0)) -> 725870.69 | N47: =SUBTOTAL(9,OFFSET(N43,1,0):OFFSET(N47,-1,0)) -> 857312.28
A49: X | B49: Balance Sheet Toggles | D49: Balance Sheet
D50: Assets
D51: Current Assets
...

Sheet DCF
B3: =Comp_Name -> Nu Scale | C3: | Discounted Cash Flow Analysis
B4: \
B6: WACC Assumptions
B8: Cost of Equity (CAPM) | H8: Current Share Price: | I8: =Current_Price -> 44.25
B9: 10 Year T-Bill Rate | C9: =Risk_Free_Rate -> 0.0409
B10: Equity Risk Premium | C10: =Equity_Risk_Premium -> 0.07
B11: Country Risk Premium | C11: =Country_RP -> 0.006
B12: Size Risk Premium | C12: =Size_RP -> 0
B13: Company Equity Beta | C13: =Equity_Beta -> 1.754
B14: CAPM Cost of Equity | C14: =Cost_of_Equity -> 0.174204
B16: Cost of Debt
B17: Assumed Effective Tax Rate | C17: =Tax_Rate -> 0.1737
B18: Debt Adjustment Factor | C18: =Debt_Adj_Factor -> 1.38
B19: After-Tax Cost of Debt | C19: =Cost_of_Debt -> 0.046638025
B21: WACC Calculation
B22: =Assumptions!$A$25 -> Equity Shares Outstanding (K) | C22: =Shares_Out -> 133890
B23: =Assumptions!$A$26 -> Company Capitalization ($K)
B24: Market Value of Equity | C24: =Equity_MV -> 5924632.5 | D24: =C24/C$26 -> 1
B25: Market Value of Debt | C25: =Debt_MV -> 0 | D25: =C25/C$26 -> 0
B26: Total Capitalization | C26: =Total_Capitalization -> 5924632.5 | D26: =D24+D25 -> 1
B27: WACC | D27: =IF(ISNUMBER(WACC_Override),WACC_Override,WACC) -> 0.174204 | K27: WACC Override:
B29: ="Discounted Cash Flows ($"&Scale_Symbol&")" -> Discounted Cash Flows ($K)
D30: Historic | E30: Projected
B31: Fiscal Year Ending | D31: =Financials!I6 -> 45657 | E31: =EOMONTH(D31,12) -> 46022 | F31: =EOMONTH(E31,12) -> 46387 | G31: =EOMONTH(F31,12) -> 46752 | H31: =EOMONTH(G31,12) -> 47118 | I31: =EOMONTH(H31,12) -> 47483
B33: Operating Income (EBIT) | D33: =INDEX(Financials!$24:$24,MATCH(D$31,Financials!$6:$6,0)) -> -138725 | E33: =INDEX(Financials!$24:$24,MATCH(E$31,Financials!$6:$6,0)) -> -137436.95 | F33: =INDEX(Financials!$24:$24,MATCH(F$31,Financials!$6:$6,0)) -> -124471.2 | G33: =INDEX(Financials!$24:$24,MATCH(G$31,Financials!$6:$6,0)) -> -66384.64 | H33: =INDEX(Financials!$24:$24,MATCH(H$31,Financials!$6:$6,0)) -> 58418.483 | I33: =INDEX(Financials!$24:$24,MATCH(I$31,Financials!$6:$6,0)) -> 131441.59
B34: Est. Cash Taxes | D34: =Financials!I39 -> 0 | E34: =Financials!J39 -> 0 | F34: =Financials!K39 -> 0 | G34: =Financials!L39 -> 0 | H34: =Financials!M39 -> 0 | I34: =Financials!N39 -> 0
B35: NOPAT* | D35: =D33+D34 -> -138725 | E35: =E33+E34 -> -137436.95 | F35: =F33+F34 -> -124471.2 | G35: =G33+G34 -> -66384.64 | H35: =H33+H34 -> 58418.483 | I35: =I33+I34 -> 131441.59
B36: Change in Working Capital (-) | D36: =INDEX(Financials!$109:$109,MATCH(D$31,Financials!$6:$6,0)) -> 0 | E36: =INDEX(Financials!$109:$109,MATCH(E$31,Financials!$6:$6,0)) -> -53055.574 | F36: =INDEX(Financials!$109:$109,MATCH(F$31,Financials!$6:$6,0)) -> 35611.175 | G36: =INDEX(Financials!$109:$109,MATCH(G$31,Financials!$6:$6,0)) -> 18700.362 | H36: =INDEX(Financials!$109:$109,MATCH(H$31,Financials!$6:$6,0)) -> 105934.91 | I36: =INDEX(Financials!$109:$109,MATCH(I$31,Financials!$6:$6,0)) -> 280186.54
B37: D&A (+) | D37: =INDEX(Financials!$110:$110,MATCH(D$31,Financials!$6:$6,0)) -> 0 | E37: =INDEX(Financials!$110:$110,MATCH(E$31,Financials!$6:$6,0)) -> 1431.0546 | F37: =INDEX(Financials!$110:$110,MATCH(F$31,Financials!$6:$6,0)) -> 2001.293 | G37: =INDEX(Financials!$110:$110,MATCH(G$31,Financials!$6:$6,0)) -> 3874.4597 | H37: =INDEX(Financials!$110:$110,MATCH(H$31,Financials!$6:$6,0)) -> 7647.6203 | I37: =INDEX(Financials!$110:$110,MATCH(I$31,Financials!$6:$6,0)) -> 13876.172
B38: Capex (-) | D38: =INDEX(Financials!$114:$114,MATCH(D$31,Financials!$6:$6,0)) -> 0 | E38: =INDEX(Financials!$114:$114,MATCH(E$31,Financials!$6:$6,0)) -> -2031.8652 | F38: =INDEX(Financials!$114:$114,MATCH(F$31,Financials!$6:$6,0)) -> -3090.0743 | G38: =INDEX(Financials!$114:$114,MATCH(G$31,Financials!$6:$6,0)) -> -6151.3084 | H38: =INDEX(Financials!$114:$114,MATCH(H$31,Financials!$6:$6,0)) -> -13811.179 | I38: =INDEX(Financials!$114:$114,MATCH(I$31,Financials!$6:$6,0)) -> -24564.23
B39: Free Cash Flow (FCFF) | D39: =SUM(D35:D38) -> -138725 | E39: =SUM(E35:E38) -> -191093.33 | F39: =SUM(F35:F38) -> -89948.807 | G39: =SUM(G35:G38) -> -49961.126 | H39: =SUM(H35:H38) -> 158189.83 | I39: =SUM(I35:I38) -> 400940.07
B40: Discount Factor | D40: =(1+$D$27)^D41 -> 1 | E40: =(1+$D$27)^E41 -> 1.0331002 | F40: =(1+$D$27)^F41 -> 1.2130704 | G40: =(1+$D$27)^G41 -> 1.4243921 | H40: =(1+$D$27)^H41 -> 1.6725269 | I40: =(1+$D$27)^I41 -> 1.9638878
B41: Discount Period | D41: 0 | E41: =YEARFRAC(TODAY(),E$31) -> 0.20277778 | F41: =E41+1 -> 1.2027778 | G41: =F41+1 -> 2.2027778 | H41: =G41+1 -> 3.2027778 | I41: =H41+1 -> 4.2027778
B43: Discounted Free Cash Flow | E43: =E39/E40 -> -184970.77 | F43: =F39/F40 -> -74149.702 | G43: =G39/G40 -> -35075.403 | H43: =H39/H40 -> 94581.338 | I43: =I39/I40 -> 204156.31
I44: *NOPAT = Net Operating Profit After Tax
B45: Perpetuity Growth Methodology | C45: Total | D45: per Share | J45: TV using Exit Multiple
B46: Perpetuity Growth Rate | C46: =Terminal_Rate -> 0.02 | J46: TV/Sales Multiple | K46: ='EV-Sales Multiples'!D29 -> 107.67238
B47: Terminal Value | C47: =K49 -> 36032172 | D47: =C47/Shares_Out -> 269.11772 | J47: Sales (FY 29) | K47: =Financials!N11 -> 657207.94
B48: Discounted Terminal Value | C48: =C47/I$40 -> 18347368 | D48: =C48/Shares_Out -> 137.03315 | J48: TV | K48: =K46*K47 -> 70763141
B49: Sum of DCFs | C49: =SUM(D$43:I$43) -> 4541.773 | D49: =C49/Shares_Out -> 0.033921675 | J49: PV | K49: =K48/I40 -> 36032172
...

Sheet DCF (H-Model for TV)
B3: =Comp_Name -> Nu Scale | C3: | Discounted Cash Flow Analysis
B6: WACC Assumptions
B8: Cost of Equity (CAPM) | H8: Current Share Price: | I8: =Current_Price -> 44.25
B9: 10 Year T-Bill Rate | C9: =Risk_Free_Rate -> 0.0409
B10: Equity Risk Premium | C10: =Equity_Risk_Premium -> 0.07
B11: Country Risk Premium | C11: =Country_RP -> 0.006
B12: Size Risk Premium | C12: =Size_RP -> 0
B13: Company Equity Beta | C13: =Equity_Beta -> 1.754
B14: CAPM Cost of Equity | C14: =Cost_of_Equity -> 0.174204
B16: Cost of Debt
B17: Assumed Effective Tax Rate | C17: =Tax_Rate -> 0.1737
B18: Debt Adjustment Factor | C18: =Debt_Adj_Factor -> 1.38
B19: After-Tax Cost of Debt | C19: =Cost_of_Debt -> 0.046638025
B21: WACC Calculation
B22: =Assumptions!$A$25 -> Equity Shares Outstanding (K) | C22: =Shares_Out -> 133890
B23: =Assumptions!$A$26 -> Company Capitalization ($K)
B24: Market Value of Equity | C24: =Equity_MV -> 5924632.5 | D24: =C24/C$26 -> 1
B25: Market Value of Debt | C25: =Debt_MV -> 0 | D25: =C25/C$26 -> 0
B26: Total Capitalization | C26: =Total_Capitalization -> 5924632.5 | D26: =D24+D25 -> 1
B27: WACC | D27: =IF(ISNUMBER(WACC_Override),WACC_Override,WACC) -> 0.174204 | K27: WACC Override:
B29: ="Discounted Cash Flows ($"&Scale_Symbol&")" -> Discounted Cash Flows ($K)
D30: Historic | E30: Projected
B31: Fiscal Year Ending | D31: =Financials!I6 -> 45657 | E31: =EOMONTH(D31,12) -> 46022 | F31: =EOMONTH(E31,12) -> 46387 | G31: =EOMONTH(F31,12) -> 46752 | H31: =EOMONTH(G31,12) -> 47118 | I31: =EOMONTH(H31,12) -> 47483
B33: Operating Income (EBIT) | D33: =INDEX(Financials!$24:$24,MATCH(D$31,Financials!$6:$6,0)) -> -138725 | E33: =INDEX(Financials!$24:$24,MATCH(E$31,Financials!$6:$6,0)) -> -137436.95 | F33: =INDEX(Financials!$24:$24,MATCH(F$31,Financials!$6:$6,0)) -> -124471.2 | G33: =INDEX(Financials!$24:$24,MATCH(G$31,Financials!$6:$6,0)) -> -66384.64 | H33: =INDEX(Financials!$24:$24,MATCH(H$31,Financials!$6:$6,0)) -> 58418.483 | I33: =INDEX(Financials!$24:$24,MATCH(I$31,Financials!$6:$6,0)) -> 131441.59
B34: Est. Cash Taxes | D34: =Financials!I39 -> 0 | E34: =Financials!J39 -> 0 | F34: =Financials!K39 -> 0 | G34: =Financials!L39 -> 0 | H34: =Financials!M39 -> 0 | I34: =Financials!N39 -> 0
B35: NOPAT* | D35: =D33+D34 -> -138725 | E35: =E33+E34 -> -137436.95 | F35: =F33+F34 -> -124471.2 | G35: =G33+G34 -> -66384.64 | H35: =H33+H34 -> 58418.483 | I35: =I33+I34 -> 131441.59
B36: Change in Working Capital (-) | D36: =INDEX(Financials!$109:$109,MATCH(D$31,Financials!$6:$6,0)) -> 0 | E36: =INDEX(Financials!$109:$109,MATCH(E$31,Financials!$6:$6,0)) -> -53055.574 | F36: =INDEX(Financials!$109:$109,MATCH(F$31,Financials!$6:$6,0)) -> 35611.175 | G36: =INDEX(Financials!$109:$109,MATCH(G$31,Financials!$6:$6,0)) -> 18700.362 | H36: =INDEX(Financials!$109:$109,MATCH(H$31,Financials!$6:$6,0)) -> 105934.91 | I36: =INDEX(Financials!$109:$109,MATCH(I$31,Financials!$6:$6,0)) -> 280186.54
B37: D&A (+) | D37: =INDEX(Financials!$110:$110,MATCH(D$31,Financials!$6:$6,0)) -> 0 | E37: =INDEX(Financials!$110:$110,MATCH(E$31,Financials!$6:$6,0)) -> 1431.0546 | F37: =INDEX(Financials!$110:$110,MATCH(F$31,Financials!$6:$6,0)) -> 2001.293 | G37: =INDEX(Financials!$110:$110,MATCH(G$31,Financials!$6:$6,0)) -> 3874.4597 | H37: =INDEX(Financials!$110:$110,MATCH(H$31,Financials!$6:$6,0)) -> 7647.6203 | I37: =INDEX(Financials!$110:$110,MATCH(I$31,Financials!$6:$6,0)) -> 13876.172
B38: Capex (-) | D38: =INDEX(Financials!$114:$114,MATCH(D$31,Financials!$6:$6,0)) -> 0 | E38: =INDEX(Financials!$114:$114,MATCH(E$31,Financials!$6:$6,0)) -> -2031.8652 | F38: =INDEX(Financials!$114:$114,MATCH(F$31,Financials!$6:$6,0)) -> -3090.0743 | G38: =INDEX(Financials!$114:$114,MATCH(G$31,Financials!$6:$6,0)) -> -6151.3084 | H38: =INDEX(Financials!$114:$114,MATCH(H$31,Financials!$6:$6,0)) -> -13811.179 | I38: =INDEX(Financials!$114:$114,MATCH(I$31,Financials!$6:$6,0)) -> -24564.23
B39: Free Cash Flow (FCFF) | D39: =SUM(D35:D38) -> -138725 | E39: =SUM(E35:E38) -> -191093.33 | F39: =SUM(F35:F38) -> -89948.807 | G39: =SUM(G35:G38) -> -49961.126 | H39: =SUM(H35:H38) -> 158189.83 | I39: =SUM(I35:I38) -> 400940.07
B40: Discount Factor | D40: =(1+$D$27)^D41 -> 1 | E40: =(1+$D$27)^E41 -> 1.0331002 | F40: =(1+$D$27)^F41 -> 1.2130704 | G40: =(1+$D$27)^G41 -> 1.4243921 | H40: =(1+$D$27)^H41 -> 1.6725269 | I40: =(1+$D$27)^I41 -> 1.9638878
B41: Discount Period | D41: 0 | E41: =YEARFRAC(TODAY(),E$31) -> 0.20277778 | F41: =E41+1 -> 1.2027778 | G41: =F41+1 -> 2.2027778 | H41: =G41+1 -> 3.2027778 | I41: =H41+1 -> 4.2027778
B43: Discounted Free Cash Flow | E43: =E39/E40 -> -184970.77 | F43: =F39/F40 -> -74149.702 | G43: =G39/G40 -> -35075.403 | H43: =H39/H40 -> 94581.338 | I43: =I39/I40 -> 204156.31
I44: *NOPAT = Net Operating Profit After Tax
B45: Perpetuity Growth Methodology | C45: Total | D45: per Share
B46: Initial High Growth Rate | C46: 0.05
B47: Life of High Growth Period | C47: 5
B48: Half Life of High Growth Period | C48: =IFERROR(C47/2,0) -> 2.5
B49: Perpetuity Growth Rate | C49: =Terminal_Rate -> 0.02
B50: Terminal Value | C50: =DCF!K49 -> 36032172 | D50: =C50/Shares_Out -> 269.11772
...

Sheet P-S Multiples
A1: P/S Market Multiples
A3: Peer Group: | D3: =Comp_Name -> Nu Scale | G3: FCEL | J3: EOSE | M3: HYLN | Q3: Peer Group Average
B5: Year | D5: Low | E5: High | G5: Low | H5: High | J5: Low | K5: High | M5: Low | N5: High | Q5: Low | R5: High
A7: Market Price | B7: {=INDEX(Annual_Periods,1)} -> 44560 | D7: 8.56 | E7: 11.72 | G7: 153.3015 | H7: 838.81 | J7: 7.52 | K7: 30.44 | M7: 5.82 | N7: 20.78 | Q7: =AVERAGE(D7, G7, J7, M7) -> 43.800375 | R7: =AVERAGE(E7, H7, K7, N7) -> 225.4375
B8: =EOMONTH(B7,12) -> 44926 | D8: 8.96 | E8: 15.32 | G8: 76.5 | H8: 208.2021 | J8: 0.97 | K8: 7.6 | M8: 2.19 | N8: 6.28 | Q8: =AVERAGE(D8, G8, J8, M8) -> 22.155 | R8: =AVERAGE(E8, H8, K8, N8) -> 59.350525
B9: =EOMONTH(B8,12) -> 45291 | D9: 2.08 | E9: 11.06 | G9: 30.9003 | H9: 127.5013 | J9: 1.02 | K9: 5.03 | M9: 0.541 | N9: 3.74 | Q9: =AVERAGE(D9, G9, J9, M9) -> 8.635325 | R9: =AVERAGE(E9, H9, K9, N9) -> 36.832825
B10: =EOMONTH(B9,12) -> 45657 | D10: 1.92 | E10: 30.21 | G10: 5.7 | H10: 46.2 | J10: 0.6447 | K10: 5.17 | M10: 0.8137 | N10: 3.84 | Q10: =AVERAGE(D10, G10, J10, M10) -> 2.2696 | R10: =AVERAGE(E10, H10, K10, N10) -> 21.355
A12: Sales (per Share) | B12: =B7 -> 44560 | D12: 0.1 | G12: 6.24 | J12: 0.09 | M12: 6.66 | Q12: =AVERAGE(D12, G12, J12, M12) -> 3.2725
B13: =B8 -> 44926 | D13: 0.23 | G13: 10.22 | J13: 0.29 | M13: 11.3 | Q13: =AVERAGE(D13, G13, J13, M13) -> 5.51
B14: =B9 -> 45291 | D14: 0.31 | G14: 8.82 | J14: 0.13 | M14: 11.72 | Q14: =AVERAGE(D14, G14, J14, M14) -> 5.245
B15: =B10 -> 45657 | D15: 0.4 | G15: 6.73 | J15: 0.07 | M15: 10.87 | Q15: =AVERAGE(D15, G15, J15, M15) -> 4.5175
A17: P/S Ratio | B17: =B7 -> 44560 | D17: =IFERROR(IF(INDEX(D$7:D$10,MATCH($B17,$B$7:$B$10,0))/INDEX(D$12:D$15,MATCH($B17,$B$12:$B$15,0))<0,"NM",INDEX(D$7:D$10,MATCH($B17,$B$7:$B$10,0))/INDEX(D$12:D$15,MATCH($B17,$B$12:$B$15,0))),"NA") -> 85.6 | E17: =IFERROR(IF(INDEX(E$7:E$10,MATCH($B17,$B$7:$B$10,0))/INDEX(D$12:D$15,MATCH($B17,$B$12:$B$15,0))<0,"NM",INDEX(E$7:E$10,MATCH($B17,$B$7:$B$10,0))/INDEX(D$12:D$15,MATCH($B17,$B$12:$B$15,0))),"NA") -> 117.2 | G17: =IFERROR(IF(INDEX(G$7:G$10,MATCH($B17,$B$7:$B$10,0))/INDEX(G$12:G$15,MATCH($B17,$B$12:$B$15,0))<0,"NM",INDEX(G$7:G$10,MATCH($B17,$B$7:$B$10,0))/INDEX(G$12:G$15,MATCH($B17,$B$12:$B$15,0))),"NA") -> 24.567548 | H17: =IFERROR(IF(INDEX(H$7:H$10,MATCH($B17,$B$7:$B$10,0))/INDEX(G$12:G$15,MATCH($B17,$B$12:$B$15,0))<0,"NM",INDEX(H$7:H$10,MATCH($B17,$B$7:$B$10,0))/INDEX(G$12:G$15,MATCH($B17,$B$12:$B$15,0))),"NA") -> 134.42468 | J17: =IFERROR(IF(INDEX(J$7:J$10,MATCH($B17,$B$7:$B$10,0))/INDEX(J$12:J$15,MATCH($B17,$B$12:$B$15,0))<0,"NM",INDEX(J$7:J$10,MATCH($B17,$B$7:$B$10,0))/INDEX(J$12:J$15,MATCH($B17,$B$12:$B$15,0))),"NA") -> 83.555556 | K17: =IFERROR(IF(INDEX(K$7:K$10,MATCH($B17,$B$7:$B$10,0))/INDEX(J$12:J$15,MATCH($B17,$B$12:$B$15,0))<0,"NM",INDEX(K$7:K$10,MATCH($B17,$B$7:$B$10,0))/INDEX(J$12:J$15,MATCH($B17,$B$12:$B$15,0))),"NA") -> 338.22222 | M17: =IFERROR(IF(INDEX(M$7:M$10,MATCH($B17,$B$7:$B$10,0))/INDEX(M$12:M$15,MATCH($B17,$B$12:$B$15,0))<0,"NM",INDEX(M$7:M$10,MATCH($B17,$B$7:$B$10,0))/INDEX(M$12:M$15,MATCH($B17,$B$12:$B$15,0))),"NA") -> 0.87387387 | N17: =IFERROR(IF(INDEX(N$7:N$10,MATCH($B17,$B$7:$B$10,0))/INDEX(M$12:M$15,MATCH($B17,$B$12:$B$15,0))<0,"NM",INDEX(N$7:N$10,MATCH($B17,$B$7:$B$10,0))/INDEX(M$12:M$15,MATCH($B17,$B$12:$B$15,0))),"NA") -> 3.1201201 | Q17: =IFERROR(AVERAGE(G17,J17,M17),"NA") -> 36.332326 | R17: =IFERROR(AVERAGE(H17,K17,N17),"NA") -> 158.58901 | T17: =IFERROR(AVERAGE(J17,M17,Q17),"NA") -> 40.253918 | U17: =IFERROR(AVERAGE(K17,N17,R17),"NA") -> 166.64378
B18: =B8 -> 44926 | D18: =IFERROR(IF(INDEX(D$7:D$10,MATCH($B18,$B$7:$B$10,0))/INDEX(D$12:D$15,MATCH($B18,$B$12:$B$15,0))<0,"NM",INDEX(D$7:D$10,MATCH($B18,$B$7:$B$10,0))/INDEX(D$12:D$15,MATCH($B18,$B$12:$B$15,0))),"NA") -> 38.956522 | E18: =IFERROR(IF(INDEX(E$7:E$10,MATCH($B18,$B$7:$B$10,0))/INDEX(D$12:D$15,MATCH($B18,$B$12:$B$15,0))<0,"NM",INDEX(E$7:E$10,MATCH($B18,$B$7:$B$10,0))/INDEX(D$12:D$15,MATCH($B18,$B$12:$B$15,0))),"NA") -> 66.608696 | G18: =IFERROR(IF(INDEX(G$7:G$10,MATCH($B18,$B$7:$B$10,0))/INDEX(G$12:G$15,MATCH($B18,$B$12:$B$15,0))<0,"NM",INDEX(G$7:G$10,MATCH($B18,$B$7:$B$10,0))/INDEX(G$12:G$15,MATCH($B18,$B$12:$B$15,0))),"NA") -> 7.4853229 | H18: =IFERROR(IF(INDEX(H$7:H$10,MATCH($B18,$B$7:$B$10,0))/INDEX(G$12:G$15,MATCH($B18,$B$12:$B$15,0))<0,"NM",INDEX(H$7:H$10,MATCH($B18,$B$7:$B$10,0))/INDEX(G$12:G$15,MATCH($B18,$B$12:$B$15,0))),"NA") -> 20.372025 | J18: =IFERROR(IF(INDEX(J$7:J$10,MATCH($B18,$B$7:$B$10,0))/INDEX(J$12:J$15,MATCH($B18,$B$12:$B$15,0))<0,"NM",INDEX(J$7:J$10,MATCH($B18,$B$7:$B$10,0))/INDEX(J$12:J$15,MATCH($B18,$B$12:$B$15,0))),"NA") -> 3.3448276 | K18: =IFERROR(IF(INDEX(K$7:K$10,MATCH($B18,$B$7:$B$10,0))/INDEX(J$12:J$15,MATCH($B18,$B$12:$B$15,0))<0,"NM",INDEX(K$7:K$10,MATCH($B18,$B$7:$B$10,0))/INDEX(J$12:J$15,MATCH($B18,$B$12:$B$15,0))),"NA") -> 26.206897 | M18: =IFERROR(IF(INDEX(M$7:M$10,MATCH($B18,$B$7:$B$10,0))/INDEX(M$12:M$15,MATCH($B18,$B$12:$B$15,0))<0,"NM",INDEX(M$7:M$10,MATCH($B18,$B$7:$B$10,0))/INDEX(M$12:M$15,MATCH($B18,$B$12:$B$15,0))),"NA") -> 0.19380531 | N18: =IFERROR(IF(INDEX(N$7:N$10,MATCH($B18,$B$7:$B$10,0))/INDEX(M$12:M$15,MATCH($B18,$B$12:$B$15,0))<0,"NM",INDEX(N$7:N$10,MATCH($B18,$B$7:$B$10,0))/INDEX(M$12:M$15,MATCH($B18,$B$12:$B$15,0))),"NA") -> 0.55575221 | Q18: =IFERROR(AVERAGE(G18,J18,M18),"NA") -> 3.6746519 | R18: =IFERROR(AVERAGE(H18,K18,N18),"NA") -> 15.711558 | T18: =IFERROR(AVERAGE(J18,M18,Q18),"NA") -> 2.4044283 | U18: =IFERROR(AVERAGE(K18,N18,R18),"NA") -> 14.158069
B19: =B9 -> 45291 | D19: =IFERROR(IF(INDEX(D$7:D$10,MATCH($B19,$B$7:$B$10,0))/INDEX(D$12:D$15,MATCH($B19,$B$12:$B$15,0))<0,"NM",INDEX(D$7:D$10,MATCH($B19,$B$7:$B$10,0))/INDEX(D$12:D$15,MATCH($B19,$B$12:$B$15,0))),"NA") -> 6.7096774 | E19: =IFERROR(IF(INDEX(E$7:E$10,MATCH($B19,$B$7:$B$10,0))/INDEX(D$12:D$15,MATCH($B19,$B$12:$B$15,0))<0,"NM",INDEX(E$7:E$10,MATCH($B19,$B$7:$B$10,0))/INDEX(D$12:D$15,MATCH($B19,$B$12:$B$15,0))),"NA") -> 35.677419 | G19: =IFERROR(IF(INDEX(G$7:G$10,MATCH($B19,$B$7:$B$10,0))/INDEX(G$12:G$15,MATCH($B19,$B$12:$B$15,0))<0,"NM",INDEX(G$7:G$10,MATCH($B19,$B$7:$B$10,0))/INDEX(G$12:G$15,MATCH($B19,$B$12:$B$15,0))),"NA") -> 3.5034354 | H19: =IFERROR(IF(INDEX(H$7:H$10,MATCH($B19,$B$7:$B$10,0))/INDEX(G$12:G$15,MATCH($B19,$B$12:$B$15,0))<0,"NM",INDEX(H$7:H$10,MATCH($B19,$B$7:$B$10,0))/INDEX(G$12:G$15,MATCH($B19,$B$12:$B$15,0))),"NA") -> 14.45593 | J19: =IFERROR(IF(INDEX(J$7:J$10,MATCH($B19,$B$7:$B$10,0))/INDEX(J$12:J$15,MATCH($B19,$B$12:$B$15,0))<0,"NM",INDEX(J$7:J$10,MATCH($B19,$B$7:$B$10,0))/INDEX(J$12:J$15,MATCH($B19,$B$12:$B$15,0))),"NA") -> 7.8461538 | K19: =IFERROR(IF(INDEX(K$7:K$10,MATCH($B19,$B$7:$B$10,0))/INDEX(J$12:J$15,MATCH($B19,$B$12:$B$15,0))<0,"NM",INDEX(K$7:K$10,MATCH($B19,$B$7:$B$10,0))/INDEX(J$12:J$15,MATCH($B19,$B$12:$B$15,0))),"NA") -> 38.692308 | M19: =IFERROR(IF(INDEX(M$7:M$10,MATCH($B19,$B$7:$B$10,0))/INDEX(M$12:M$15,MATCH($B19,$B$12:$B$15,0))<0,"NM",INDEX(M$7:M$10,MATCH($B19,$B$7:$B$10,0))/INDEX(M$12:M$15,MATCH($B19,$B$12:$B$15,0))),"NA") -> 0.04616041 | N19: =IFERROR(IF(INDEX(N$7:N$10,MATCH($B19,$B$7:$B$10,0))/INDEX(M$12:M$15,MATCH($B19,$B$12:$B$15,0))<0,"NM",INDEX(N$7:N$10,MATCH($B19,$B$7:$B$10,0))/INDEX(M$12:M$15,MATCH($B19,$B$12:$B$15,0))),"NA") -> 0.31911263 | Q19: =IFERROR(AVERAGE(G19,J19,M19),"NA") -> 3.7985832 | R19: =IFERROR(AVERAGE(H19,K19,N19),"NA") -> 17.82245 | T19: =IFERROR(AVERAGE(J19,M19,Q19),"NA") -> 3.8969658 | U19: =IFERROR(AVERAGE(K19,N19,R19),"NA") -> 18.944623
